#VRML_SIM R2023b utf8

EXTERNPROTO "https://raw.githubusercontent.com/cyberbotics/webots/R2023b/projects/objects/backgrounds/protos/TexturedBackground.proto"
EXTERNPROTO "https://raw.githubusercontent.com/cyberbotics/webots/R2023b/projects/objects/backgrounds/protos/TexturedBackgroundLight.proto"
EXTERNPROTO "https://raw.githubusercontent.com/cyberbotics/webots/R2023b/projects/objects/floors/protos/RectangleArena.proto"
EXTERNPROTO "../protos/MyCobot280Pi.proto"
EXTERNPROTO "../protos/TurtleBot3Waffle.proto"
EXTERNPROTO "../protos/MyCobot280Pi_solid.proto"
EXTERNPROTO "../protos/gripper_v2.proto"

WorldInfo {
}
Viewpoint {
  orientation 0.2440823485155742 0.387015201453318 -0.8891811069670619 1.2338387749053277
  position -0.680831635853366 2.4830603946281 0.9908052042111242
}
TexturedBackground {
}
TexturedBackgroundLight {
}
RectangleArena {
  floorSize 5 5
}
Robot {
  translation -0.42 -0.81 0
  children [
    Solid {
      translation 0 0 0.11
      children [
        DEF GRIPPER_BASE_POSE Pose {
          children [
            DEF GRIPPER_BASE_SHAPE Shape {
              appearance PBRAppearance {
                roughness 1
                metalness 0
              }
              geometry Mesh {
                url [
                  "../protos/gripper/gripper_body.obj"
                ]
              }
              castShadows FALSE
            }
          ]
        }
        DEF GRIPPER_RIGHT_BASE_OUTER HingeJoint {
          jointParameters HingeJointParameters {
            axis 0 1 0
          }
          device [
            RotationalMotor {
              name "gripper_right::base_outer::rotational_motor"
            }
            PositionSensor {
              name "gripper_right::base_outer::position_sensor"
            }
          ]
          endPoint Solid {
            translation -0.005 0 -0.0095
            rotation 0 1 0 0
            children [
              Shape {
                appearance PBRAppearance {
                  roughness 1
                  metalness 0
                }
                geometry Mesh {
                  url [
                    "../protos/gripper/v2/gripper_right_outer.obj"
                  ]
                }
                castShadows FALSE
              }
              DEF GRIPPER_RIGHT_OUTER_PADDLE HingeJoint {
                jointParameters HingeJointParameters {
                  axis 0 1 0
                  anchor 0.04 0 -0.015
                }
                device [
                  RotationalMotor {
                    name "gripper_right::outer_paddle::rotational_motor"
                  }
                  PositionSensor {
                    name "gripper_right::outer_paddle::position_sensor"
                  }
                ]
                endPoint Solid {
                  rotation 0 1 0 0
                  children [
                    DEF GRIPPER_RIGHT_PADDLE_SHAPE Shape {
                      appearance PBRAppearance {
                        roughness 1
                        metalness 0
                      }
                      geometry Mesh {
                        url [
                          "../protos/gripper/v2/gripper_right_paddle.obj"
                        ]
                      }
                      castShadows FALSE
                    }
                    HingeJoint {
                      jointParameters HingeJointParameters {
                        axis 0 1 0
                        anchor 0.033 0 -0.038
                      }
                      device [
                        RotationalMotor {
                          name "gripper_right::paddle::rotational_motor"
                        }
                        PositionSensor {
                          name "gripper_right::paddle::position_sensor"
                        }
                      ]
                      endPoint Solid {
                        translation 0.033 0 -0.038
                        rotation 0 1 0 0
                        name "gripper_right::paddle_joint"
                      }
                    }
                  ]
                  name "gripper_right::paddle"
                }
              }
            ]
            name "gripper_right::outer"
          }
        }
        DEF GRIPPER_RIGHT_BASE_INNER HingeJoint {
          jointParameters HingeJointParameters {
            axis 0 1 0
            anchor -0.005 0 -0.0295
          }
          device [
            RotationalMotor {
              name "gripper_right::base_inner::rotational_motor"
            }
            PositionSensor {
              name "gripper_right::base_inner::position_sensor"
            }
          ]
          endPoint Solid {
            translation -0.005 0 -0.009500000000000001
            rotation 0 1 0 0
            children [
              DEF GRIPPER_RIGHT_INNER_SHAPE Shape {
                appearance PBRAppearance {
                  roughness 1
                  metalness 0
                }
                geometry Mesh {
                  url [
                    "../protos/gripper/v2/gripper_right_inner.obj"
                  ]
                }
                castShadows FALSE
              }
              DEF GRIPPER_RIGHT_INNER_PADDLE HingeJoint {
                jointParameters HingeJointParameters {
                  axis 0 1 0
                  anchor 0.033 0 -0.038
                }
                endPoint SolidReference {
                  solidName "gripper_right::paddle_joint"
                }
              }
              DEF GRIPPER_RIGHT_INNER_OUTER HingeJoint {
                jointParameters HingeJointParameters {
                  axis 0 1 0
                }
                endPoint SolidReference {
                  solidName "gripper_right::outer"
                }
              }
            ]
            name "gripper_right::inner"
          }
        }
        DEF GRIPPER_LEFT_BASE_OUTER HingeJoint {
          jointParameters HingeJointParameters {
            axis 0 1 0
          }
          device [
            RotationalMotor {
              name "gripper_left::base_outer::rotational_motor"
            }
            PositionSensor {
              name "gripper_left::base_outer::position_sensor"
            }
          ]
          endPoint Solid {
            translation -0.006 0 -0.0095
            rotation 0 1 0 0
            children [
              Shape {
                appearance PBRAppearance {
                  roughness 1
                  metalness 0
                }
                geometry Mesh {
                  url [
                    "../protos/gripper/v2/gripper_left_outer.obj"
                  ]
                }
                castShadows FALSE
              }
              DEF GRIPPER_LEFT_OUTER_PADDLE HingeJoint {
                jointParameters HingeJointParameters {
                  axis 0 1 0
                  anchor 0.04 0 -0.015
                }
                device [
                  RotationalMotor {
                    name "gripper_left::outer_paddle::rotational_motor"
                  }
                  PositionSensor {
                    name "gripper_left::outer_paddle::position_sensor"
                  }
                ]
                endPoint Solid {
                  rotation 0 1 0 0
                  children [
                    Shape {
                      appearance PBRAppearance {
                        roughness 1
                        metalness 0
                      }
                      geometry Mesh {
                        url [
                          "../protos/gripper/v2/gripper_left_paddle.obj"
                        ]
                      }
                      castShadows FALSE
                    }
                  ]
                  name "gripper_left::paddle"
                }
              }
            ]
            name "gripper_left::outer"
          }
        }
        DEF GRIPPER_LEFT_BASE_INNER HingeJoint {
          jointParameters HingeJointParameters {
            axis 0 1 0
            anchor -0.006 0 -0.0295
          }
          device [
            RotationalMotor {
              name "gripper_left::base_inner::rotational_motor"
            }
            PositionSensor {
              name "gripper_left::base_inner::position_sensor"
            }
          ]
          endPoint Solid {
            translation -0.006 0 -0.009500000000000001
            rotation 0 1 0 0
            children [
              DEF GRIPPER_LEFT_INNER_SHAPE Shape {
                appearance PBRAppearance {
                  roughness 1
                  metalness 0
                }
                geometry Mesh {
                  url [
                    "../protos/gripper/v2/gripper_left_inner.obj"
                  ]
                }
                castShadows FALSE
              }
            ]
            name "gripper_left::inner"
          }
        }
      ]
    }
  ]
  physics Physics {
  }
  controller "gripper_test"
}
MyCobot280Pi {
  translation 0 0 0.05
  controller "mycobot_enhance"
  gripper_slot [
    Solid {
      translation 2.644e-08 0.01 0.04
      rotation 1 4.7949e-09 1.32679e-06 3.14159
      children [
        DEF GRIPPER_BASE_POSE Pose {
          children [
            DEF GRIPPER_BASE_SHAPE Shape {
              appearance PBRAppearance {
                roughness 1
                metalness 0
              }
              geometry Mesh {
              }
              castShadows FALSE
            }
          ]
        }
        DEF GRIPPER_RIGHT_BASE_OUTER HingeJoint {
          jointParameters HingeJointParameters {
            axis 0 1 0
          }
          device [
            RotationalMotor {
              name "gripper_right::base_outer::rotational_motor"
            }
            PositionSensor {
              name "gripper_right::base_outer::position_sensor"
            }
          ]
          endPoint Solid {
            translation -0.005 0 -0.009
            rotation 0 1 0 0
            children [
              Shape {
                appearance PBRAppearance {
                  roughness 1
                  metalness 0
                }
                geometry Mesh {
                  url [
                    "C:/Users/JordenHuang/webotsProject/mycobot_turtlebot/protos/gripper/v2/gripper_right_outer.obj"
                  ]
                }
                castShadows FALSE
              }
              DEF GRIPPER_RIGHT_OUTER_PADDLE HingeJoint {
                jointParameters HingeJointParameters {
                  axis 0 1 0
                  anchor 0.045 0 -0.015
                }
                device [
                  RotationalMotor {
                    name "gripper_right::outer_paddle::rotational_motor"
                  }
                  PositionSensor {
                    name "gripper_right::outer_paddle::position_sensor"
                  }
                ]
                endPoint Solid {
                  rotation 0 1 0 0
                  children [
                    DEF GRIPPER_RIGHT_PADDLE_SHAPE Shape {
                      appearance PBRAppearance {
                        roughness 1
                        metalness 0
                      }
                      geometry Mesh {
                        url [
                          "C:/Users/JordenHuang/webotsProject/mycobot_turtlebot/protos/gripper/v2/gripper_right_paddle.obj"
                        ]
                      }
                      castShadows FALSE
                    }
                  ]
                  name "gripper_right::paddle"
                  boundingObject Pose {
                    translation 0.027 0.003 -0.055
                    children [
                      Box {
                        size 0.015 0.022 0.025
                      }
                    ]
                  }
                  physics Physics {
                    density -1
                    mass 0.001
                  }
                }
              }
            ]
            name "gripper_right::outer"
            boundingObject Pose {
              translation 0.04 0.006 -0.015
              children [
                Box {
                  size 0.01 0.015 0.01
                }
              ]
            }
            physics Physics {
              density -1
              mass 0.001
            }
          }
        }
        DEF GRIPPER_RIGHT_BASE_INNER HingeJoint {
          jointParameters HingeJointParameters {
            axis 0 1 0
            anchor -0.005 0 -0.0295
          }
          device [
            RotationalMotor {
              name "gripper_right::base_inner::rotational_motor"
            }
            PositionSensor {
              name "gripper_right::base_inner::position_sensor"
            }
          ]
          endPoint Solid {
            translation -0.005000000000000005 0 -0.009500000000000001
            rotation 0 1 0 0
            children [
              DEF GRIPPER_RIGHT_INNER_SHAPE Shape {
                appearance PBRAppearance {
                  roughness 1
                  metalness 0
                }
                geometry Mesh {
                  url [
                    "C:/Users/JordenHuang/webotsProject/mycobot_turtlebot/protos/gripper/v2/gripper_right_inner.obj"
                  ]
                }
                castShadows FALSE
              }
            ]
            name "gripper_right::inner"
            boundingObject Pose {
              translation 0.022 0.006 -0.03
              children [
                Box {
                  size 0.01 0.015 0.01
                }
              ]
            }
            physics Physics {
              density -1
              mass 0.001
            }
          }
        }
        DEF GRIPPER_LEFT_BASE_OUTER HingeJoint {
          jointParameters HingeJointParameters {
            axis 0 1 0
          }
          device [
            RotationalMotor {
              name "gripper_left::base_outer::rotational_motor"
            }
            PositionSensor {
              name "gripper_left::base_outer::position_sensor"
            }
          ]
          endPoint Solid {
            translation -0.006 0 -0.0095
            rotation 0 1 0 0
            children [
              Shape {
                appearance PBRAppearance {
                  roughness 1
                  metalness 0
                }
                geometry Mesh {
                  url [
                    "C:/Users/JordenHuang/webotsProject/mycobot_turtlebot/protos/gripper/v2/gripper_left_outer.obj"
                  ]
                }
                castShadows FALSE
              }
              DEF GRIPPER_LEFT_OUTER_PADDLE HingeJoint {
                jointParameters HingeJointParameters {
                  axis 0 1 0
                  anchor -0.04 0 -0.015
                }
                device [
                  RotationalMotor {
                    name "gripper_left::outer_paddle::rotational_motor"
                  }
                  PositionSensor {
                    name "gripper_left::outer_paddle::position_sensor"
                  }
                ]
                endPoint Solid {
                  rotation 0 1 0 0
                  children [
                    DEF GRIPPER_LEFT_PADDLE_SHAPE Shape {
                      appearance PBRAppearance {
                        roughness 1
                        metalness 0
                      }
                      geometry Mesh {
                        url [
                          "C:/Users/JordenHuang/webotsProject/mycobot_turtlebot/protos/gripper/v2/gripper_left_paddle.obj"
                        ]
                      }
                      castShadows FALSE
                    }
                  ]
                  name "gripper_left::paddle"
                  boundingObject Pose {
                    translation -0.028 0.003 -0.055
                    children [
                      Box {
                        size 0.015 0.022 0.025
                      }
                    ]
                  }
                  physics Physics {
                    density -1
                    mass 0.001
                  }
                }
              }
            ]
            name "gripper_left::outer"
            boundingObject Pose {
              translation -0.042 0.006 -0.015
              children [
                Box {
                  size 0.01 0.015 0.01
                }
              ]
            }
            physics Physics {
              density -1
              mass 0.001
            }
          }
        }
        DEF GRIPPER_LEFT_BASE_INNER HingeJoint {
          jointParameters HingeJointParameters {
            axis 0 1 0
            anchor -0.006 0 -0.0295
          }
          device [
            RotationalMotor {
              name "gripper_left::base_inner::rotational_motor"
            }
            PositionSensor {
              name "gripper_left::base_inner::position_sensor"
            }
          ]
          endPoint Solid {
            translation -0.006 0 -0.009500000000000001
            rotation 0 1 0 0
            children [
              DEF GRIPPER_LEFT_INNER_SHAPE Shape {
                appearance PBRAppearance {
                  roughness 1
                  metalness 0
                }
                geometry Mesh {
                  url [
                    "C:/Users/JordenHuang/webotsProject/mycobot_turtlebot/protos/gripper/v2/gripper_left_inner.obj"
                  ]
                }
                castShadows FALSE
              }
            ]
            name "gripper_left::inner"
            boundingObject Pose {
              translation -0.022 0.006 -0.03
              children [
                Box {
                  size 0.01 0.015 0.01
                }
              ]
            }
            physics Physics {
              density -1
              mass 0.001
            }
          }
        }
      ]
      name "GripperV2"
      boundingObject Pose {
        translation -0.005 0.025 -0.005
        children [
          Box {
            size 0.06 0.06 0.065
          }
        ]
      }
      physics Physics {
        density -1
        mass 0.01
        centerOfMass [
          0 -1 0.07
        ]
      }
    }
  ]
}
TurtleBot3Waffle {
  hidden rotation_3 -0.4625644367367229 0.8864690380384141 0.014380071824807548 0.00024613470145456285
  hidden rotation_4 -0.4625644367367229 0.8864690380384141 0.014380071824807548 0.00024613470145456285
  translation 0 1.4 0
  controller "turcobot_control"
  arm_slot [
    DEF BASE MyCobot280Pi_solid {
      translation -0.12 -0.06 0.12
      gripper_slot [
        gripper_v2 {
        }
      ]
    }
  ]
}
